<?xml version="1.0"?>
<sdf version="1.6">
    <model name='typhoon_h480'>
        <pose>1.0 1.0 3.0 0 0 0</pose>

        <link name='base_link'>
            <pose frame=''>0 0 0 0 0 0</pose>

            <inertial>
                <pose frame=''>0.001005 0 -0.0090035 0 0 0</pose>
                <mass>2.02</mass>
                <inertia>
                    <ixx>0.011</ixx>
                    <ixy>0</ixy>
                    <ixz>0</ixz>
                    <iyy>0.015</iyy>
                    <iyz>0</iyz>
                    <izz>0.021</izz>
                </inertia>
            </inertial>

            <collision name='base_link_collision'>
                <pose frame=''>0 0 0.0 0 0 0</pose>
                <geometry>
                    <box>
                        <size>0.67 0.67 0.15</size>
                    </box>
                </geometry>
                <surface>
                    <contact>
                        <ode>
                            <min_depth>0.001</min_depth>
                            <max_vel>0</max_vel>
                        </ode>
                    </contact>
                    <friction>
                        <ode />
                    </friction>
                </surface>
            </collision>

            <visual name='base_link_visual'>
                <pose frame=''>0 0 0 0 0 0</pose>
                <geometry>
                    <mesh>
                        <scale>0.001 0.001 0.001</scale>
                        <uri>model://typhoon_h480/meshes/main_body_remeshed_v3.stl</uri>
                    </mesh>
                </geometry>
                <material>
                    <diffuse>1 0 0 1</diffuse>
                    <script>
                        <name>Gazebo/DarkGrey</name>
                        <uri>file://media/materials/scripts/gazebo.material</uri>
                    </script>
                </material>
            </visual>

            <gravity>1</gravity>
            <velocity_decay />
            <self_collide>0</self_collide>

            <sensor name="air_pressure_sensor" type="air_pressure">
                <always_on>1</always_on>
                <update_rate>50</update_rate>
                <air_pressure>
                    <pressure>
                        <noise type="gaussian">
                            <mean>0</mean>
                            <stddev>0.01</stddev>
                        </noise>
                    </pressure>
                </air_pressure>
            </sensor>
            <sensor name="imu_sensor" type="imu">
                <always_on>1</always_on>
                <update_rate>250</update_rate>
            </sensor>
        </link>

        <link name="left_leg">
            <inertial>
                <!-- place holder -->
                <pose frame=''>0 -0.14314 -0.207252 0 0 0</pose>
                <mass>0.1</mass>
                <inertia>
                    <ixx>0.001</ixx>
                    <ixy>0</ixy>
                    <ixz>0</ixz>
                    <iyy>0.001</iyy>
                    <iyz>0</iyz>
                    <izz>0.001</izz>
                </inertia>
            </inertial>
            <collision name='collision'>
                <pose frame=''>-0.005 -0.14314 -0.207252 0 1.56893 0</pose>
                <geometry>
                    <cylinder>
                        <radius>0.012209</radius>
                        <length>0.3</length>
                    </cylinder>
                </geometry>
                <surface>
                    <friction>
                        <ode>
                            <mu>1</mu>
                            <mu2>1</mu2>
                        </ode>
                    </friction>
                    <contact>
                        <ode>
                            <kp>1e+8</kp>
                            <kd>1</kd>
                            <max_vel>0.01</max_vel>
                            <min_depth>0.001</min_depth>
                        </ode>
                    </contact>
                </surface>
            </collision>
            <collision name='collision_bar'>
                <pose frame=''>0.00052 -0.08503 -0.121187 -0.501318 0 0</pose>
                <geometry>
                    <cylinder>
                        <radius>0.00914984</radius>
                        <length>0.176893</length>
                    </cylinder>
                </geometry>
                <surface>
                    <friction>
                        <ode>
                            <mu>1</mu>
                            <mu2>1</mu2>
                        </ode>
                    </friction>
                    <contact>
                        <ode>
                            <kp>1e+8</kp>
                            <kd>1</kd>
                            <max_vel>0.01</max_vel>
                            <min_depth>0.001</min_depth>
                        </ode>
                    </contact>
                </surface>
            </collision>
            <visual name='base_link_left_leg'>
                <pose frame=''>0 0 0 0 0 0</pose>
                <geometry>
                    <mesh>
                        <scale>0.001 0.001 0.001</scale>
                        <uri>model://typhoon_h480/meshes/leg2_remeshed_v3.stl</uri>
                    </mesh>
                </geometry>
                <material>
                    <lighting>1</lighting>
                    <script>
                        <uri>file://media/materials/scripts/gazebo.material</uri>
                        <name>Gazebo/DarkGrey</name>
                    </script>
                    <ambient>0.3 0.3 0.3 1</ambient>
                    <diffuse>0.7 0.7 0.7 1</diffuse>
                    <specular>0.01 0.01 0.01 1</specular>
                    <emissive>0 0 0 1</emissive>
                </material>
            </visual>
        </link>
        <joint name='left_leg_joint' type='revolute'>
            <child>left_leg</child>
            <parent>base_link</parent>
            <pose frame=''>0.00026 -0.040515 -0.048 0 0 0</pose>
            <axis>
                <xyz>-1 0 0</xyz>
                <limit>
                    <lower>0</lower>
                    <upper>1</upper>
                    <effort>100</effort>
                    <velocity>-1</velocity>
                    <stiffness>100000000</stiffness>
                    <dissipation>1</dissipation>
                </limit>
                <dynamics>
                    <damping>0.1</damping>
                </dynamics>
                <use_parent_model_frame>1</use_parent_model_frame>
            </axis>
            <physics>
                <ode>
                    <implicit_spring_damper>1</implicit_spring_damper>
                </ode>
            </physics>
        </joint>

        <link name="right_leg">
            <pose frame=''>0 0 0 0 0 0</pose>
            <inertial>
                <!-- place holder -->
                <pose frame=''>0 0.14314 -0.207252 0 0 0</pose>
                <mass>0.1</mass>
                <inertia>
                    <ixx>0.001</ixx>
                    <ixy>0</ixy>
                    <ixz>0</ixz>
                    <iyy>0.001</iyy>
                    <iyz>0</iyz>
                    <izz>0.001</izz>
                </inertia>
            </inertial>
            <collision name='collision'>
                <pose frame=''>-0.005 0.14314 -0.207252 0 1.56893 0</pose>
                <geometry>
                    <cylinder>
                        <radius>0.012209</radius>
                        <length>0.3</length>
                    </cylinder>
                </geometry>
                <surface>
                    <friction>
                        <ode>
                            <mu>1</mu>
                            <mu2>1</mu2>
                        </ode>
                    </friction>
                    <contact>
                        <ode>
                            <kp>1e+8</kp>
                            <kd>1</kd>
                            <max_vel>0.01</max_vel>
                            <min_depth>0.001</min_depth>
                        </ode>
                    </contact>
                </surface>
            </collision>
            <collision name='collision_bar'>
                <pose frame=''>0.00052 0.08503 -0.121187 0.501318 0 0</pose>
                <geometry>
                    <cylinder>
                        <radius>0.00914984</radius>
                        <length>0.176893</length>
                    </cylinder>
                </geometry>
                <surface>
                    <friction>
                        <ode>
                            <mu>1</mu>
                            <mu2>1</mu2>
                        </ode>
                    </friction>
                    <contact>
                        <ode>
                            <kp>1e+8</kp>
                            <kd>1</kd>
                            <max_vel>0.01</max_vel>
                            <min_depth>0.001</min_depth>
                        </ode>
                    </contact>
                </surface>
            </collision>
            <visual name='base_link_right_leg'>
                <pose frame=''>0 0 0 0 0 0</pose>
                <geometry>
                    <mesh>
                        <scale>0.001 0.001 0.001</scale>
                        <uri>model://typhoon_h480/meshes/leg1_remeshed_v3.stl</uri>
                    </mesh>
                </geometry>
                <material>
                    <lighting>1</lighting>
                    <script>
                        <uri>file://media/materials/scripts/gazebo.material</uri>
                        <name>Gazebo/DarkGrey</name>
                    </script>
                    <ambient>0.3 0.3 0.3 1</ambient>
                    <diffuse>0.7 0.7 0.7 1</diffuse>
                    <specular>0.01 0.01 0.01 1</specular>
                    <emissive>0 0 0 1</emissive>
                </material>
            </visual>
        </link>
        <joint name='right_leg_joint' type='revolute'>
            <child>right_leg</child>
            <parent>base_link</parent>
            <pose frame=''>0.00026 0.040515 -0.048 0 0 0</pose>
            <axis>
                <xyz>1 0 0</xyz>
                <limit>
                    <lower>0</lower>
                    <upper>1</upper>
                    <effort>100</effort>
                    <velocity>-1</velocity>
                    <stiffness>100000000</stiffness>
                    <dissipation>1</dissipation>
                </limit>
                <dynamics>
                    <damping>0.1</damping>
                </dynamics>
                <use_parent_model_frame>1</use_parent_model_frame>
            </axis>
            <physics>
                <ode>
                    <implicit_spring_damper>1</implicit_spring_damper>
                </ode>
            </physics>
        </joint>

        <plugin filename="gz-sim-joint-position-controller-system"
            name="gz::sim::systems::JointPositionController">
            <joint_name>left_leg_joint</joint_name>
            <joint_name>right_leg_joint</joint_name>
            <sub_topic>servo_0</sub_topic>
            <p_gain>10.0</p_gain>
        </plugin>

        <link name='rotor_0'>
            <pose frame=''>-0.00187896 -0.242705 0.0822169 0 0 -2.09439510239</pose>
            <inertial>
                <pose frame=''>0 0 0 0 0 0</pose>
                <mass>0.005</mass>
                <inertia>
                    <ixx>9.75e-07</ixx>
                    <ixy>0</ixy>
                    <ixz>0</ixz>
                    <iyy>0.000273104</iyy>
                    <iyz>0</iyz>
                    <izz>0.000274004</izz>
                </inertia>
            </inertial>
            <collision name='rotor_0_collision'>
                <pose frame=''>0 0 0 0 0 0</pose>
                <geometry>
                    <cylinder>
                        <length>0.005</length>
                        <radius>0.128</radius>
                    </cylinder>
                </geometry>
                <surface>
                    <contact>
                        <ode />
                    </contact>
                    <friction>
                        <ode />
                    </friction>
                </surface>
            </collision>
            <visual name='rotor_0_visual'>
                <pose frame=''>0.00187896 -0.242705 -0.0822169 0 0 0</pose>
                <geometry>
                    <mesh>
                        <scale>0.001 0.001 0.001</scale>
                        <uri>model://typhoon_h480/meshes/prop_cw_assembly_remeshed_v3.stl</uri>
                    </mesh>
                </geometry>
                <material>
                    <diffuse>0 0 1 1</diffuse>
                    <script>
                        <name>Gazebo/Blue</name>
                        <uri>file://media/materials/scripts/gazebo.material</uri>
                    </script>
                </material>
            </visual>
            <gravity>1</gravity>
            <velocity_decay />
            <self_collide>0</self_collide>
        </link>
        <joint name='rotor_0_joint' type='revolute'>
            <child>rotor_0</child>
            <parent>base_link</parent>
            <axis>
                <xyz>-0.033996 -0.0006 0.68216</xyz>
                <limit>
                    <lower>-1e+16</lower>
                    <upper>1e+16</upper>
                    <effort>10</effort>
                    <velocity>-1</velocity>
                </limit>
                <dynamics>
                    <damping>0.005</damping>
                </dynamics>
                <use_parent_model_frame>1</use_parent_model_frame>
            </axis>
            <physics>
                <ode>
                    <implicit_spring_damper>1</implicit_spring_damper>
                </ode>
            </physics>
        </joint>
        <plugin filename="gz-sim-multicopter-motor-model-system"
            name="gz::sim::systems::MulticopterMotorModel">
            <jointName>rotor_0_joint</jointName>
            <linkName>rotor_0</linkName>
            <turningDirection>cw</turningDirection>
            <timeConstantUp>0.0125</timeConstantUp>
            <timeConstantDown>0.025</timeConstantDown>
            <maxRotVelocity>1000.0</maxRotVelocity>
            <motorConstant>8.54858e-06</motorConstant>
            <momentConstant>0.016</momentConstant>
            <commandSubTopic>command/motor_speed</commandSubTopic>
            <motorNumber>0</motorNumber>
            <rotorDragCoefficient>8.06428e-05</rotorDragCoefficient>
            <rollingMomentCoefficient>1e-06</rollingMomentCoefficient>
            <rotorVelocitySlowdownSim>10</rotorVelocitySlowdownSim>
            <motorType>velocity</motorType>
        </plugin>

        <link name='rotor_1'>
            <pose frame=''>-0.00187896 0.242705 0.0822169 0 0 0</pose>
            <inertial>
                <pose frame=''>0 0 0 0 0 0</pose>
                <mass>0.005</mass>
                <inertia>
                    <ixx>9.75e-07</ixx>
                    <ixy>0</ixy>
                    <ixz>0</ixz>
                    <iyy>0.000273104</iyy>
                    <iyz>0</iyz>
                    <izz>0.000274004</izz>
                </inertia>
            </inertial>
            <collision name='rotor_1_collision'>
                <pose frame=''>0 0 0 0 0 0</pose>
                <geometry>
                    <cylinder>
                        <length>0.005</length>
                        <radius>0.128</radius>
                    </cylinder>
                </geometry>
                <surface>
                    <contact>
                        <ode />
                    </contact>
                    <friction>
                        <ode />
                    </friction>
                </surface>
            </collision>
            <visual name='rotor_1_visual'>
                <pose frame=''>-0.211396 -0.119762 -0.082219 0 0 0</pose>
                <geometry>
                    <mesh>
                        <scale>0.001 0.001 0.001</scale>
                        <uri>model://typhoon_h480/meshes/prop_ccw_assembly_remeshed_v3.stl</uri>
                    </mesh>
                </geometry>
                <material>
                    <diffuse>0 0 1 1</diffuse>
                    <script>
                        <name>Gazebo/Blue</name>
                        <uri>file://media/materials/scripts/gazebo.material</uri>
                    </script>
                </material>
            </visual>
            <gravity>1</gravity>
            <velocity_decay />
            <self_collide>0</self_collide>
        </link>
        <joint name='rotor_1_joint' type='revolute'>
            <child>rotor_1</child>
            <parent>base_link</parent>
            <axis>
                <xyz>-0.09563 -0.0003 1.8976</xyz>
                <limit>
                    <lower>-1e+16</lower>
                    <upper>1e+16</upper>
                    <effort>10</effort>
                    <velocity>-1</velocity>
                </limit>
                <dynamics>
                    <damping>0.005</damping>
                </dynamics>
                <use_parent_model_frame>1</use_parent_model_frame>
            </axis>
            <physics>
                <ode>
                    <implicit_spring_damper>1</implicit_spring_damper>
                </ode>
            </physics>
        </joint>
        <plugin filename="gz-sim-multicopter-motor-model-system"
            name="gz::sim::systems::MulticopterMotorModel">
            <jointName>rotor_1_joint</jointName>
            <linkName>rotor_1</linkName>
            <turningDirection>ccw</turningDirection>
            <timeConstantUp>0.0125</timeConstantUp>
            <timeConstantDown>0.025</timeConstantDown>
            <maxRotVelocity>1000.0</maxRotVelocity>
            <motorConstant>8.54858e-06</motorConstant>
            <momentConstant>0.016</momentConstant>
            <commandSubTopic>command/motor_speed</commandSubTopic>
            <motorNumber>1</motorNumber>
            <rotorDragCoefficient>8.06428e-05</rotorDragCoefficient>
            <rollingMomentCoefficient>1e-06</rollingMomentCoefficient>
            <rotorVelocitySlowdownSim>10</rotorVelocitySlowdownSim>
            <motorType>velocity</motorType>
        </plugin>

        <link name='rotor_2'>
            <pose frame=''>0.211396 0.119762 0.082219 0 0 0</pose>
            <inertial>
                <pose frame=''>0 0 0 0 0 0</pose>
                <mass>0.005</mass>
                <inertia>
                    <ixx>9.75e-07</ixx>
                    <ixy>0</ixy>
                    <ixz>0</ixz>
                    <iyy>0.000273104</iyy>
                    <iyz>0</iyz>
                    <izz>0.000274004</izz>
                </inertia>
            </inertial>
            <collision name='rotor_2_collision'>
                <pose frame=''>0 0 0 0 0 0</pose>
                <geometry>
                    <cylinder>
                        <length>0.005</length>
                        <radius>0.128</radius>
                    </cylinder>
                </geometry>
                <surface>
                    <contact>
                        <ode />
                    </contact>
                    <friction>
                        <ode />
                    </friction>
                </surface>
            </collision>
            <visual name='rotor_2_visual'>
                <pose frame=''>0.00187896 -0.242705 -0.0822169 0 0 0</pose>
                <geometry>
                    <mesh>
                        <scale>0.001 0.001 0.001</scale>
                        <uri>model://typhoon_h480/meshes/prop_cw_assembly_remeshed_v3.stl</uri>
                    </mesh>
                </geometry>
                <material>
                    <diffuse>1 0 0 1</diffuse>
                    <script>
                        <name>Gazebo/Blue</name>
                        <uri>file://media/materials/scripts/gazebo.material</uri>
                    </script>
                </material>
            </visual>
            <gravity>1</gravity>
            <velocity_decay />
            <self_collide>0</self_collide>
        </link>
        <joint name='rotor_2_joint' type='revolute'>
            <child>rotor_2</child>
            <parent>base_link</parent>
            <axis>
                <xyz>0.0446 -0.0825 1.8977</xyz>
                <limit>
                    <lower>-1e+16</lower>
                    <upper>1e+16</upper>
                    <effort>10</effort>
                    <velocity>-1</velocity>
                </limit>
                <dynamics>
                    <damping>0.005</damping>
                </dynamics>
                <use_parent_model_frame>1</use_parent_model_frame>
            </axis>
            <physics>
                <ode>
                    <implicit_spring_damper>1</implicit_spring_damper>
                </ode>
            </physics>
        </joint>
        <plugin filename="gz-sim-multicopter-motor-model-system"
            name="gz::sim::systems::MulticopterMotorModel">
            <jointName>rotor_2_joint</jointName>
            <linkName>rotor_2</linkName>
            <turningDirection>cw</turningDirection>
            <timeConstantUp>0.0125</timeConstantUp>
            <timeConstantDown>0.025</timeConstantDown>
            <maxRotVelocity>1000.0</maxRotVelocity>
            <motorConstant>8.54858e-06</motorConstant>
            <momentConstant>0.016</momentConstant>
            <commandSubTopic>command/motor_speed</commandSubTopic>
            <motorNumber>2</motorNumber>
            <rotorDragCoefficient>8.06428e-05</rotorDragCoefficient>
            <rollingMomentCoefficient>1e-06</rollingMomentCoefficient>
            <rotorVelocitySlowdownSim>10</rotorVelocitySlowdownSim>
            <motorType>velocity</motorType>
        </plugin>

        <link name='rotor_3'>
            <pose frame=''>-0.209396 -0.122762 0.082219 0 0 2.09439510239</pose>
            <inertial>
                <pose frame=''>0 0 0 0 0 0</pose>
                <mass>0.005</mass>
                <inertia>
                    <ixx>9.75e-07</ixx>
                    <ixy>0</ixy>
                    <ixz>0</ixz>
                    <iyy>0.000273104</iyy>
                    <iyz>0</iyz>
                    <izz>0.000274004</izz>
                </inertia>
            </inertial>
            <collision name='rotor_3_collision'>
                <pose frame=''>0 0 0 0 0 0</pose>
                <geometry>
                    <cylinder>
                        <length>0.005</length>
                        <radius>0.128</radius>
                    </cylinder>
                </geometry>
                <surface>
                    <contact>
                        <ode />
                    </contact>
                    <friction>
                        <ode />
                    </friction>
                </surface>
            </collision>
            <visual name='rotor_3_visual'>
                <pose frame=''>-0.211396 -0.119762 -0.082219 0 0 0</pose>
                <geometry>
                    <mesh>
                        <scale>0.001 0.001 0.001</scale>
                        <uri>model://typhoon_h480/meshes/prop_ccw_assembly_remeshed_v3.stl</uri>
                    </mesh>
                </geometry>
                <material>
                    <diffuse>1 0 0 1</diffuse>
                    <script>
                        <name>Gazebo/Blue</name>
                        <uri>file://media/materials/scripts/gazebo.material</uri>
                    </script>
                </material>
            </visual>
            <gravity>1</gravity>
            <velocity_decay />
            <self_collide>0</self_collide>
        </link>
        <joint name='rotor_3_joint' type='revolute'>
            <child>rotor_3</child>
            <parent>base_link</parent>
            <axis>
                <xyz>0.0404 -0.0876 1.8976</xyz>
                <limit>
                    <lower>-1e+16</lower>
                    <upper>1e+16</upper>
                    <effort>10</effort>
                    <velocity>-1</velocity>
                </limit>
                <dynamics>
                    <damping>0.005</damping>
                </dynamics>
                <use_parent_model_frame>1</use_parent_model_frame>
            </axis>
            <physics>
                <ode>
                    <implicit_spring_damper>1</implicit_spring_damper>
                </ode>
            </physics>
        </joint>
        <plugin filename="gz-sim-multicopter-motor-model-system"
            name="gz::sim::systems::MulticopterMotorModel">
            <jointName>rotor_3_joint</jointName>
            <linkName>rotor_3</linkName>
            <turningDirection>ccw</turningDirection>
            <timeConstantUp>0.0125</timeConstantUp>
            <timeConstantDown>0.025</timeConstantDown>
            <maxRotVelocity>1000.0</maxRotVelocity>
            <motorConstant>8.54858e-06</motorConstant>
            <momentConstant>0.016</momentConstant>
            <commandSubTopic>command/motor_speed</commandSubTopic>
            <motorNumber>3</motorNumber>
            <rotorDragCoefficient>8.06428e-05</rotorDragCoefficient>
            <rollingMomentCoefficient>1e-06</rollingMomentCoefficient>
            <rotorVelocitySlowdownSim>10</rotorVelocitySlowdownSim>
            <motorType>velocity</motorType>
        </plugin>

        <link name='rotor_4'>
            <pose frame=''>0.211396 -0.119762 0.082219 0 0 -2.09439510239</pose>
            <inertial>
                <pose frame=''>0 0 0 0 0 0</pose>
                <mass>0.005</mass>
                <inertia>
                    <ixx>9.75e-07</ixx>
                    <ixy>0</ixy>
                    <ixz>0</ixz>
                    <iyy>0.000273104</iyy>
                    <iyz>0</iyz>
                    <izz>0.000274004</izz>
                </inertia>
            </inertial>
            <collision name='rotor_4_collision'>
                <pose frame=''>0 0 0 0 0 0</pose>
                <geometry>
                    <cylinder>
                        <length>0.005</length>
                        <radius>0.128</radius>
                    </cylinder>
                </geometry>
                <surface>
                    <contact>
                        <ode />
                    </contact>
                    <friction>
                        <ode />
                    </friction>
                </surface>
            </collision>
            <visual name='rotor_4_visual'>
                <pose frame=''>-0.211396 -0.119762 -0.082219 0 0 0</pose>
                <geometry>
                    <mesh>
                        <scale>0.001 0.001 0.001</scale>
                        <uri>model://typhoon_h480/meshes/prop_ccw_assembly_remeshed_v3.stl</uri>
                    </mesh>
                </geometry>
                <material>
                    <diffuse>0 0 1 1</diffuse>
                    <script>
                        <name>Gazebo/Blue</name>
                        <uri>file://media/materials/scripts/gazebo.material</uri>
                    </script>
                </material>
            </visual>
            <gravity>1</gravity>
            <velocity_decay />
            <self_collide>0</self_collide>
        </link>
        <joint name='rotor_4_joint' type='revolute'>
            <child>rotor_4</child>
            <parent>base_link</parent>
            <axis>
                <xyz>0.0486 0.0811 1.8976</xyz>
                <limit>
                    <lower>-1e+16</lower>
                    <upper>1e+16</upper>
                    <effort>10</effort>
                    <velocity>-1</velocity>
                </limit>
                <dynamics>
                    <damping>0.005</damping>
                </dynamics>
                <use_parent_model_frame>1</use_parent_model_frame>
            </axis>
            <physics>
                <ode>
                    <implicit_spring_damper>1</implicit_spring_damper>
                </ode>
            </physics>
        </joint>
        <plugin filename="gz-sim-multicopter-motor-model-system"
            name="gz::sim::systems::MulticopterMotorModel">
            <jointName>rotor_4_joint</jointName>
            <linkName>rotor_4</linkName>
            <turningDirection>ccw</turningDirection>
            <timeConstantUp>0.0125</timeConstantUp>
            <timeConstantDown>0.025</timeConstantDown>
            <maxRotVelocity>1000.0</maxRotVelocity>
            <motorConstant>8.54858e-06</motorConstant>
            <momentConstant>0.016</momentConstant>
            <commandSubTopic>command/motor_speed</commandSubTopic>
            <motorNumber>4</motorNumber>
            <rotorDragCoefficient>8.06428e-05</rotorDragCoefficient>
            <rollingMomentCoefficient>1e-06</rollingMomentCoefficient>
            <rotorVelocitySlowdownSim>10</rotorVelocitySlowdownSim>
            <motorType>velocity</motorType>
        </plugin>

        <link name='rotor_5'>
            <pose frame=''>-0.209396 0.122762 0.082219 0 0 2.09439510239</pose>
            <inertial>
                <pose frame=''>0 0 0 0 0 0</pose>
                <mass>0.005</mass>
                <inertia>
                    <ixx>9.75e-07</ixx>
                    <ixy>0</ixy>
                    <ixz>0</ixz>
                    <iyy>0.000273104</iyy>
                    <iyz>0</iyz>
                    <izz>0.000274004</izz>
                </inertia>
            </inertial>
            <collision name='rotor_5_collision'>
                <pose frame=''>0 0 0 0 0 0</pose>
                <geometry>
                    <cylinder>
                        <length>0.005</length>
                        <radius>0.128</radius>
                    </cylinder>
                </geometry>
                <surface>
                    <contact>
                        <ode />
                    </contact>
                    <friction>
                        <ode />
                    </friction>
                </surface>
            </collision>
            <visual name='rotor_5_visual'>
                <pose frame=''>0.00187896 -0.242705 -0.0822169 0 0 0</pose>
                <geometry>
                    <mesh>
                        <scale>0.001 0.001 0.001</scale>
                        <uri>model://typhoon_h480/meshes/prop_cw_assembly_remeshed_v3.stl</uri>
                    </mesh>
                </geometry>
                <material>
                    <diffuse>0 0 1 1</diffuse>
                    <script>
                        <name>Gazebo/Blue</name>
                        <uri>file://media/materials/scripts/gazebo.material</uri>
                    </script>
                </material>
            </visual>
            <gravity>1</gravity>
            <velocity_decay />
            <self_collide>0</self_collide>
        </link>
        <joint name='rotor_5_joint' type='revolute'>
            <child>rotor_5</child>
            <parent>base_link</parent>
            <axis>
                <xyz>0.046 0.0827 1.8977</xyz>
                <limit>
                    <lower>-1e+16</lower>
                    <upper>1e+16</upper>
                    <effort>10</effort>
                    <velocity>-1</velocity>
                </limit>
                <dynamics>
                    <damping>0.005</damping>
                </dynamics>
                <use_parent_model_frame>1</use_parent_model_frame>
            </axis>
            <physics>
                <ode>
                    <implicit_spring_damper>1</implicit_spring_damper>
                </ode>
            </physics>
        </joint>
        <plugin filename="libgz-sim7-multicopter-motor-model-system"
            name="gz::sim::systems::MulticopterMotorModel">
            <jointName>rotor_5_joint</jointName>
            <linkName>rotor_5</linkName>
            <turningDirection>cw</turningDirection>
            <timeConstantUp>0.0125</timeConstantUp>
            <timeConstantDown>0.025</timeConstantDown>
            <maxRotVelocity>1000.0</maxRotVelocity>
            <motorConstant>8.54858e-06</motorConstant>
            <momentConstant>0.016</momentConstant>
            <commandSubTopic>command/motor_speed</commandSubTopic>
            <motorNumber>5</motorNumber>
            <rotorDragCoefficient>8.06428e-05</rotorDragCoefficient>
            <rollingMomentCoefficient>1e-06</rollingMomentCoefficient>
            <rotorVelocitySlowdownSim>10</rotorVelocitySlowdownSim>
            <motorType>velocity</motorType>
        </plugin>

        <plugin filename="gz-sim-odometry-publisher-system"
            name="gz::sim::systems::OdometryPublisher">
            <dimensions>3</dimensions>
            <odom_frame>world</odom_frame>
        </plugin>

    </model>
</sdf>
